Workbook

Sheet Compras e Custos
A1: CONTROLE DE COMPRAS — CONFEITARIA | I1: PARÂMETROS
A2: Base de custos inicial • atualize os valores sempre que fizer novas compras | I2: Acréscimo luz e gás | J2: 0.2
A4: Categoria | B4: Produto | C4: Preço pago (R$) | D4: Quantidade comprada | E4: Unidade / conteúdo | F4: Custo unitário (R$) | G4: Observações | I4: RESUMO
A5: Utilidades | B5: Papel-alumínio | C5: 4.39 | D5: 1 | E5: rolo | F5: =IF(D5=0,0,C5/D5) | I5: Subtotal das compras | J5: =SUM(C5:C54)
A6: Utilidades | B6: Plástico filme | C6: 5.59 | D6: 1 | E6: rolo | F6: =IF(D6=0,0,C6/D6) | I6: Luz e gás (20%) | J6: =J5*J2
A7: Utilidades | B7: Papel-toalha | C7: 4.39 | D7: 2 | E7: rolos | F7: =IF(D7=0,0,C7/D7) | I7: Custo total c/ luz e gás | J7: =J5+J6
A8: Utilidades | B8: Saco de confeitar | C8: 7.5 | D8: 5 | E8: unidades | F8: =IF(D8=0,0,C8/D8) | I8: Só 3ª a 6ª compra | J8: =SUMIF(G5:G54,"*Terceira*",C5:C54)+SUMIF(G5:G54,"*Quarta*",C5:C54)+SUMIF(G5:G54,"*Quinta*",C5:C54)+SUMIF(G5:G54,"*Sexta*",C5:C54)
A9: Utilidades | B9: Touca Descartável | C9: 5 | D9: 5 | E9: unidades | F9: =IF(D9=0,0,C9/D9)
A10: Utilidades | B10: Durex | C10: 4.5 | D10: 1 | E10: unidade | F10: =IF(D10=0,0,C10/D10) | I10: Adicionais | J10: Peso (g)
A11: Utilidades | B11: Grampeador com grampos | C11: 12 | D11: 1 | E11: conjunto | F11: =IF(D11=0,0,C11/D11) | I11: Granulado | J11: 5
A12: Utilidades | B12: Peneira | C12: 19.29 | D12: 1 | E12: unidade | F12: =IF(D12=0,0,C12/D12) | I12: Morango | J12: 16
A13: Ingredientes | B13: Chocolate em pó | C13: 39.8 | D13: 200 | E13: gramas | F13: =IF(D13=0,0,C13/D13) | I13: Biscoito Oreo | J13: 9
A14: Ingredientes | B14: Margarina Qualy | C14: 6.98 | D14: 250 | E14: gramas | F14: =IF(D14=0,0,C14/D14) | I14: Pacotão de Bis | J14: 6
A15: Ingredientes | B15: Paçoca | C15: 23.9 | D15: 700 | E15: gramas | F15: =IF(D15=0,0,C15/D15) | I15: Paçoca | J15: 5
A16: Ingredientes | B16: Leite em pó | C16: 8.99 | D16: 200 | E16: gramas | F16: =IF(D16=0,0,C16/D16) | I16: Leite em pó | J16: 9
A17: Ingredientes | B17: Biscoito Oreo | C17: 8.58 | D17: 180 | E17: gramas | F17: =IF(D17=0,0,C17/D17)
A18: Ingredientes | B18: Leite condensado | C18: 29.12 | D18: 1580 | E18: gramas | F18: =IF(D18=0,0,C18/D18)
A19: Ingredientes | B19: Creme de leite | C19: 14.96 | D19: 800 | E19: gramas | F19: =IF(D19=0,0,C19/D19)
A20: Ingredientes | B20: Pacote de bala | C20: 7.98 | D20: 500 | E20: gramas | F20: =IF(D20=0,0,C20/D20)
A21: Ingredientes | B21: Granulado | C21: 19.98 | D21: 400 | E21: gramas | F21: =IF(D21=0,0,C21/D21)
A22: Ingredientes | B22: Pacotão de Bis | C22: 12.98 | D22: 201.6 | E22: gramas | F22: =IF(D22=0,0,C22/D22)
A23: Ingredientes | B23: Morango | C23: 10.9 | D23: 220 | E23: gramas | F23: =IF(D23=0,0,C23/D23)
A24: Ingredientes | B24: Barra de chocolate Fracionado | C24: 29.9 | D24: 1000 | E24: gramas | F24: =IF(D24=0,0,C24/D24)
A25: Embalagens | B25: Adesivos | C25: 19.34 | D25: 70 | E25: unidades | F25: =IF(D25=0,0,C25/D25)
A26: Embalagens | B26: Pote 250 ml | C26: 15 | D26: 24 | E26: unidades | F26: =IF(D26=0,0,C26/D26)
A27: Embalagens | B27: Pote 140 ml | C27: 15.9 | D27: 25 | E27: unidades | F27: =IF(D27=0,0,C27/D27)
A28: Embalagens | B28: Forminha de brigadeiro | C28: 3.5 | D28: 100 | E28: unidades | F28: =IF(D28=0,0,C28/D28)
... A34: Embalagens | B34: Embalagem trufas | C34: 30 | D34: 300 | E34: unidades | F34: =IF(D34=0,0,C34/D34)
A35: Embalagens | B35: Saco de confeitar GRANDE | C35: 20 | D35: 10 | E35: unidades | F35: =IF(D35=0,0,C35/D35) | G35: Segunda compra
A36: Utilidades | B36: Forma pra fazer as trufas (não descartável) | C36: 35.98 | D36: 2 | E36: formas | F36: =IF(D36=0,0,C36/D36) | G36: Segunda compra - INVESTIMENTO, não descartável
A37: Ingredientes | B37: Chocolate em pó | C37: 39.9 | D37: 200 | E37: gramas | F37: =IF(D37=0,0,C37/D37) | G37: Terceira compra
A38: Ingredientes | B38: Margarina Qualy | C38: 6.98 | D38: 250 | E38: gramas | F38: =IF(D38=0,0,C38/D38) | G38: Terceira compra
A39: Embalagens | B39: Caixa para cento de doces | C39: 10.47 | D39: 3 | E39: unidades | F39: =IF(D39=0,0,C39/D39) | G39: Quarta compra
A40: Ingredientes | B40: Granulado | C40: 19.99 | D40: 1 | E40: pacote | F40: =IF(D40=0,0,C40/D40) | G40: Quarta compra (peso do pacote não informado)
A41: Ingredientes | B41: Chocolate em pó 50% | C41: 38.99 | D41: 1 | E41: pacote | F41: =IF(D41=0,0,C41/D41) | G41: Quarta compra (peso do pacote não informado)
A42: Ingredientes | B42: Leite condensado | C42: 41.44 | D42: 2370 | E42: gramas | F42: =IF(D42=0,0,C42/D42) | G42: Quarta compra (6 latas de 395 g)
A43: Ingredientes | B43: Creme de leite | C43: 21.52 | D43: 1600 | E43: gramas | F43: =IF(D43=0,0,C43/D43) | G43: Quarta compra (8 caixas de 200 g)
A44: Embalagens | B44: Forminha de brigadeiro | C44: 6 | D44: 200 | E44: unidades | F44: =IF(D44=0,0,C44/D44) | G44: Quarta compra
A45: Utilidades | B45: Saco de confeitar | C45: 13.99 | D45: 25 | E45: unidades | F45: =IF(D45=0,0,C45/D45) | G45: Quinta compra
A46: Ingredientes | B46: Coco em flocos | C46: 25.99 | D46: 500 | E46: gramas | F46: =IF(D46=0,0,C46/D46) | G46: Quinta compra
...

Sheet Por compra
A1: GASTO POR COMPRA
A3: Compra | B3: Itens | C3: Total (R$)
A4: 1ª — compra inicial | B4: =COUNTIFS('Compras e Custos'!G5:G54,"") | C4: =SUMIFS('Compras e Custos'!C5:C54,'Compras e Custos'!G5:G54,"")
A5: 2ª — segunda compra | B5: =COUNTIF('Compras e Custos'!G5:G54,"*Segunda*") | C5: =SUMIF('Compras e Custos'!G5:G54,"*Segunda*",'Compras e Custos'!C5:C54)
A6: 3ª — terceira compra | B6: =COUNTIF('Compras e Custos'!G5:G54,"*Terceira*") | C6: =SUMIF('Compras e Custos'!G5:G54,"*Terceira*",'Compras e Custos'!C5:C54)
A7: 4ª — quarta compra | B7: =COUNTIF('Compras e Custos'!G5:G54,"*Quarta*") | C7: =SUMIF('Compras e Custos'!G5:G54,"*Quarta*",'Compras e Custos'!C5:C54)
A8: 5ª — quinta compra | B8: =COUNTIF('Compras e Custos'!G5:G54,"*Quinta*") | C8: =SUMIF('Compras e Custos'!G5:G54,"*Quinta*",'Compras e Custos'!C5:C54)
A9: 6ª — sexta compra | B9: =COUNTIF('Compras e Custos'!G5:G54,"*Sexta*") | C9: =SUMIF('Compras e Custos'!G5:G54,"*Sexta*",'Compras e Custos'!C5:C54)
A10: TOTAL GERAL | B10: =SUM(B4:B9) | C10: =SUM(C4:C9)
